Workbook

Sheet Citas
A1: PLANIFICACIÓN DE CITAS — TÉCNICOS NE4 FIBRA ÓPTICA (Umtelkomd)
A2: Horario: 08:00-17:00 | Total citas: 77 | Última actualización: 07/02/2026 17:17
R3: ASIGNACIÓN DE TÉCNICOS (máx. 7)
A4: Semana | B4: Fecha | C4: Día | D4: Hora Inicio | E4: Hora Fin | F4: Nº HA | G4: Tipo de Trabajo | H4: TK Req. | I4: Unidades | J4: Tipo | K4: Cód. Postal | L4: Ciudad | M4: Dirección | N4: Código Área | O4: Contacto | P4: Email | Q4: Teléfono | R4: Técnico 1 | S4: Técnico 2 | T4: Técnico 3 | U4: Técnico 4 | V4: Técnico 5 | W4: Técnico 6 | X4: Técnico 7 | Y4: Estado | Z4: Notas Acceso | AA4: Materiales | AB4: Costo Est. (€) | AC4: Costo Real (€) | AD4: Fotos | AE4: Observaciones
A5: S07 | B5: 2026-02-09 | C5: Lunes | D5: 08:00 | E5: 12:00 | F5: HA898706 | G5: Installation + WC | H5: 3 | I5: 5 | J5: WE | K5: 32549 | M5: Bad Oeynhausen Dehme Wasserstraße 52 | N5: 01-01-05-0028-0007-Dehme | O5: Vitus Schulte | P5: verwaltung@beckschewe-immo.de | Q5: 0573153245, 05731537700 | Y5: Pendiente | Z5: Reprogramado; Tocar timbre
A6: S07 | B6: 2026-02-09 | C6: Lunes | D6: 08:00 | E6: 13:00 | F6: HA488651 | G6: Installation + WC | H6: 2 | I6: 7 | J6: WE | K6: 33428 | L6: Harsewinkel Ostheide 21 | N6: 01-03-05-0061-0002-Harsewinkel-Ost | O6: Ulrich Fritsch | P6: Ulrich-fritsch@web.de | Y6: Pendiente | Z6: Reprogramado
A7: S07 | B7: 2026-02-09 | C7: Lunes | D7: 12:00 | E7: 13:30 | F7: HA212990 | G7: Installation + WC | H7: 3 | I7: 8 | J7: WE | K7: 32816 | M7: Schieder Schwalenberg Steinheimer Straße 25 | N7: 01-03-05-0025-0003-Lothe | O7: Alexander Aulbur | P7: steinheim25@outlook.de | Y7: Pendiente | Z7: Reprogramado
A8: S07 | B8: 2026-02-09 | C8: Lunes | D8: 13:00 | E8: 17:00 | F8: HA898825 | G8: Installation + WC | H8: 3 | I8: 5 | J8: WE | K8: 32549 | L8: Bad Oeynhausen Dehmer Grund 12 | N8: 01-01-05-0028-0007-Dehme | O8: Herr Paulsmeier (ET) | P8: annette-boebau@web.de | Q8: 017644555176, 0573151678 | Y8: Pendiente | Z8: Reprogramado
A9: S07 | B9: 2026-02-10 | C9: Martes | D9: 08:00 | E9: 17:00 | F9: HA1053649 | G9: Otro | H9: 3 | I9: 8 | J9: WE | K9: 49328 | M9: Melle Buer Burtonstraße 11 | N9: 01-01-03-0079-0001-Buer-Burtonstr | P9: Kf@hensiek.com | Q9: 016092627547 | Y9: Pendiente | Z9: Reprogramado
A10: S07 | B10: 2026-02-10 | C10: Martes | D10: 08:00 | E10: 15:00 | F10: HA1053643 | G10: Otro | H10: 2 | I10: 4 | J10: WE | K10: 49328 | M10: Melle Buer Burtonstraße 27 | N10: 01-01-03-0079-0001-Buer-Burtonstr | P10: Kf@hensiek.com | Q10: 016092627547 | Y10: Pendiente | Z10: Reprogramado
A11: S07 | B11: 2026-02-11 | C11: Miércoles | D11: 08:00 | E11: 17:00 | F11: HA489775 | G11: Installation + WC | H11: 3 | I11: 10 | J11: WE | K11: 33428 | M11: Harsewinkel Thüringer Weg 4 | N11: 01-03-05-0061-0002-Harsewinkel-Ost | Y11: Pendiente | Z11: Reprogramado
A12: S07 | B12: 2026-02-11 | C12: Miércoles | D12: 08:00 | E12: 17:00 | F12: HA211385 | G12: Installation + WC | H12: 2 | I12: 6 | J12: WE | K12: 32816 | M12: Schieder Schwalenberg Marktstraße 3 | N12: 01-03-05-0029-0003-Schwalenberg | O12: Annegret Dreyer | Y12: Pendiente | Z12: Reprogramado
A13: S07 | B13: 2026-02-12 | C13: Jueves | D13: 08:00 | E13: 17:00 | F13: HA211475 | G13: Installation + WC | H13: 2 | I13: 8 | J13: WE | K13: 32816 | M13: Schieder Schwalenberg U | N13: 01-03-05-0029-0003-Schwalenberg | O13: Andrea Wlodarczyk | P13: wlodarczyk@t-online.de | Q13: +4952845239 | Y13: Pendiente | Z13: Reprogramado
A14: S07 | B14: 2026-02-12 | C14: Jueves | D14: 08:00 | E14: 17:00 | F14: HA755683 | G14: Installation + WC | H14: 2 | I14: 5 | J14: WE | K14: 49143 | M14: Bissendorf Bad Essener Straße 4 | N14: 01-01-03-0072-0001-Schledehausen | O14: Gerd Vrieler | Y14: Pendiente | Z14: Reprogramado
A15: S07 | B15: 2026-02-13 | C15: Viernes | D15: 08:00 | E15: 15:00 | F15: HA1053641 | G15: Otro | H15: 2 | I15: 4 | J15: WE | K15: 49328 | M15: Melle Buer Burtonstraße 29 | N15: 01-01-03-0079-0001-Buer-Burtonstr | P15: Kf@hensiek.com | Q15: 016092627547 | Y15: Pendiente | Z15: Reprogramado
A16: S07 | B16: 2026-02-13 | C16: Viernes | D16: 08:00 | E16: 17:00 | F16: HA1053638 | G16: Otro | H16: 3 | I16: 6 | J16: WE | K16: 49328 | M16: Melle Buer Burtonstraße 33 | N16: 01-01-03-0079-0001-Buer-Burtonstr | P16: Kf@hensiek.com | Q16: 016092627547 | Y16: Pendiente | Z16: Reprogramado
A17: S08 | B17: 2026-02-16 | C17: Lunes | D17: 08:00 | E17: 17:00 | F17: HA707397 | G17: Installation + WC | H17: 2 | I17: 4 | J17: WE | K17: 33014 | M17: Bad Driburg Hildegundestraße 15 | N17: 01-03-05-0076-0004-BDrib-Kern | O17: Gerd Wöstenkühler | P17: gwoesten@web.de | Y17: Pendiente | Z17: Reprogramado
A18: S08 | B18: 2026-02-16 | C18: Lunes | D18: 08:00 | E18: 15:00 | F18: HA211369 | G18: Installation + WC | H18: 2 | I18: 43 | J18: WE | K18: 32816 | M18: Schieder Schwalenberg Neue Torstraße 55 | N18: 01-03-05-0029-0003-Schwalenberg | P18: gfh-mom@t-online.de | Q18: +49528496161 | Y18: Pendiente | Z18: Reprogramado
A19: S08 | B19: 2026-02-16 | C19: Lunes | D19: 08:00 | E19: 12:00 | F19: HA754424 | G19: Installation + WC | H19: 2 | I19: 6 | J19: WE | K19: 49143 | M19: Bissendorf Ulrichstraße 5 | N19: 01-01-03-0069-0001-NatbergenJeggen | O19: Martin Sauer | P19: martin.rulle@t-online.de | Q19: 015144556070 | Y19: Pendiente | Z19: Tocar timbre
A20: S08 | B20: 2026-02-17 | C20: Martes | D20: 08:00 | E20: 17:00 | F20: HA212903 | G20: Installation + WC | H20: 2 | I20: 4 | J20: WE | K20: 32816 | M20: Schieder Schwalenberg Steinheimer Straße 24 | N20: 01-03-05-0025-0003-Lothe | O20: Thomas Fiene | P20: Info@fiene-wohnen.de | Q20: +491705445508 | Y20: Pendiente | Z20: Reprogramado
A21: S08 | B21: 2026-02-17 | C21: Martes | D21: 08:00 | E21: 17:00 | F21: HA488691 | G21: Installation + WC | H21: 2 | I21: 6 | J21: WE | K21: 33428 | M21: Harsewinkel Pappelweg 15 | N21: 01-03-05-0061-0002-Harsewinkel-Ost | O21: Altmeyer Immobilien | P21: Laudage@altmeyer-immobilien.de | Q21: 0524792272022 | Y21: Pendiente | Z21: Reprogramado
A22: S08 | B22: 2026-02-17 | C22: Martes | D22: 08:00 | E22: 17:00 | F22: HA485462 | G22: Installation | H22: 1 | I22: 4 | J22: WE | K22: 33428 | M22: Harsewinkel Ahornweg 30 | N22: 01-03-05-0060-0002-Harsewinkel-Wes | O22: Altmeyer Immobilien | Y22: Pendiente | Z22: Reprogramado
A23: S08 | B23: 2026-02-18 | C23: Miércoles | D23: 08:00 | E23: 17:00 | F23: HA706980 | G23: WC | H23: 2 | I23: 4 | J23: WE | K23: 33014 | M23: Bad Driburg Caspar Heinrich Straße 10 | N23: 01-03-05-0076-0004-BDrib-Kern | O23: Herr Schönhoff | P23: Bsch@Schoenhoff.de | Q23: 01725252167, 01732933183 | Y23: Pendiente | Z23: Reprogramado
A24: S08 | B24: 2026-02-18 | C24: Miércoles | D24: 08:00 | E24: 14:00 | F24: HA485469 | G24: Installation + WC | H24: 2 | I24: 3 | J24: WE | K24: 33428 | M24: Harsewinkel Ahornweg 37 | N24: 01-03-05-0061-0002-Harsewinkel-Ost | O24: Heinz Schößler | P24: heinz2025@gmx.de | Q24: 015751166087, 01745760498 | Y24: Pendiente | Z24: Reprogramado
A25: S08 | B25: 2026-02-18 | C25: Miércoles | D25: 08:00 | E25: 17:00 | F25: HA487787 | G25: Installation + WC | H25: 1 | I25: 8 | J25: WE | K25: 33428 | M25: Harsewinkel Harsewinkel Jahnstraße 6 | N25: 01-03-05-0061-0002-Harsewinkel-Ost | P25: louisinhetveld@gmail.com | Q25: 01601861127, 016094739398 | Y25: Pendiente | Z25: Reprogramado; Nueva construcción; Llave necesaria; Director de obra en sitio
A26: S08 | B26: 2026-02-19 | C26: Jueves | D26: 08:00 | E26: 15:00 | F26: HA754999 | G26: Installation + WC | H26: 2 | I26: 3 | J26: WE | K26: 49143 | L26: Bissendorf Schledehausen Kleiner Zuschlag 15 | N26: 01-01-03-0072-0001-Schledehausen | O26: Christian Heißing | P26: christian@heissing.de | Y26: Pendiente | Z26: Reprogramado
A27: S08 | B27: 2026-02-19 | C27: Jueves | D27: 08:00 | E27: 14:00 | F27: HA430733 | G27: Installation | H27: 2 | I27: 4 | J27: WE | K27: 49163 | M27: Bohmte Brockstraße 3 | N27: 01-01-03-0065-0001-Bohmte | O27: Johanna Meyer | P27: j-meyer18@web.de | Y27: Pendiente | Z27: Reprogramado
A28: S08 | B28: 2026-02-20 | C28: Viernes | D28: 08:00 | E28: 12:00 | F28: HA707839 | G28: Installation + WC | H28: 3 | I28: 7 | J28: WE | K28: 33014 | M28: Bad Driburg Lange Straße 95 | N28: 01-03-05-0076-0004-BDrib-Kern | O28: Ejves Tominaj | P28: Zumbraunenhirschen@t-online.de | Y28: Pendiente | Z28: Reprogramado
A29: S08 | B29: 2026-02-20 | C29: Viernes | D29: 08:00 | E29: 17:00 | F29: HA488698 | G29: Installation + WC | H29: 3 | I29: 8 | J29: WE | K29: 33428 | M29: Harsewinkel Pappelweg 9 | N29: 01-03-05-0061-0002-Harsewinkel-Ost | P29: Info@korf-gmbh.de | Y29: Pendiente | Z29: Reprogramado
A30: S08 | B30: 2026-02-20 | C30: Viernes | D30: 13:00 | E30: 17:00 | F30: HA707146 | G30: Installation | H30: 4 | I30: 7 | J30: WE | K30: 33014 | M30: Bad Driburg Eggiweg 2 | N30: 01-03-05-0076-0004-BDrib-Kern | O30: Magdalena Ziegerowski | P30: japur@t-online.de | Y30: Pendiente
A31: S09 | B31: 2026-02-23 | C31: Lunes | D31: 08:00 | E31: 15:00 | F31: HA755769 | G31: Installation + WC | H31: 2 | I31: 4 | J31: WH | K31: 49143 | M31: Bissendorf Bergstr. 15 | N31: 01-01-03-0072-0001-Schledehausen | O31: Jörg Läkamp | P31: j.laekamp@osnanet.de | Q31: 017663218739 | Y31: Pendiente | Z31: Reprogramado
A32: S09 | B32: 2026-02-23 | C32: Lunes | D32: 08:00 | E32: 15:30 | F32: HA754767 | G32: Installation + WC | H32: 2 | I32: 3 | J32: WH | K32: 49143 | M32: Bissendorf Südstraße 5 | N32: 01-01-03-0069-0001-NatbergenJeggen | O32: Ralf Moor | P32: info@zaunmoor.de | Q32: 01758004913, 054024895 | Y32: Pendiente | Z32: Reprogramado
A33: S09 | B33: 2026-02-23 | C33: Lunes | D33: 08:00 | E33: 15:00 | F33: HA755773 | G33: Installation + WC | H33: 2 | I33: 4 | J33: WH | K33: 49143 | M33: Bissendorf Bergstr. 13 | N33: 01-01-03-0072-0001-Schledehausen | O33: Jörg Läkamp | P33: j.laekamp@osnanet.de | Q33: 017663218739 | Y33: Pendiente | Z33: Reprogramado
A34: S09 | B34: 2026-02-24 | C34: Martes | D34: 08:00 | E34: 14:00 | F34: HA754073 | G34: Installation + WC | H34: 2 | I34: 3 | J34: WH | K34: 49143 | M34: Bissendorf Mindenerstr.55 | N34: 01-01-03-0069-0001-NatbergenJeggen | O34: Rena Karpasand | P34: karpasand@gmx.de | Q34: +4954026919991, 015170842533 | Y34: Pendiente | Z34: Reprogramado
A35: S09 | B35: 2026-02-24 | C35: Martes | D35: 08:00 | E35: 17:00 | F35: HA755803 | G35: Installation + WC | H35: 4 | I35: 10 | J35: WH | K35: 49143 | M35: Bissendorf Heinrich Gerdom Straße 19 | N35: 01-01-03-0072-0001-Schledehausen | O35: Maschmeyer Immobilien | P35: pantke@immobilien-maschmeyer.de | Y35: Pendiente | Z35: Reprogramado
A36: S09 | B36: 2026-02-25 | C36: Miércoles | D36: 08:00 | E36: 17:00 | F36: HA409104 | G36: Installation | H36: 3 | I36: 6 | J36: WE | K36: 34414 | M36: Warburg Warburg Fichtenweg 1 | N36: 01-03-05-0039-0010-Warburg-Z | O36: Carsten Wolff | P36: carsten@wolff-rehermann.de | Q36: 01712379749 | Y36: Pendiente | Z36: Reprogramado
A37: S09 | B37: 2026-02-25 | C37: Miércoles | D37: 08:00 | E37: 12:00 | F37: HA755688 | G37: Installation + WC | H37: 2 | I37: 3 | J37: WH | K37: 49143 | M37: Bissendorf Dürerstraße 5 | N37: 01-01-03-0072-0001-Schledehausen | O37: Roland Arndt | P37: roland.arndt@osnanet.de | Q37: 01717853841, 0540299500 | Y37: Pendiente | Z37: Reprogramado
A38: S09 | B38: 2026-02-25 | C38: Miércoles | D38: 13:00 | E38: 17:00 | F38: HA1118948 | G38: Installation + WC | H38: 2 | I38: 3 | J38: WE | K38: 49086 | M38: Osnabrück Darum Gretesch Lüstringen Mindener Straße 441 | N38: 01-01-03-0084-0001-Lüstringen-OSt | O38: Andreas Lüttig | P38: Aluettig1971@gmail.com | Q38: 08437329 | Y38: Pendiente | Z38: Reprogramado
A39: S09 | B39: 2026-02-26 | C39: Jueves | D39: 08:00 | E39: 17:00 | F39: HA706882 | G39: WC | H39: 2 | I39: 7 | J39: WE | K39: 33014 | M39: Bad Driburg Bernhard Brinkmöller Straße 17 | N39: 01-03-05-0076-0004-BDrib-Kern | O39: Ejves Tominaj | P39: Zumbraunenhirschen@t-online.de | Y39: Pendiente | Z39: Reprogramado
A40: S09 | B40: 2026-02-26 | C40: Jueves | D40: 08:00 | E40: 17:00 | F40: HA707405 | G40: Installation + WC | H40: 2 | I40: 3 | J40: WE | K40: 33014 | M40: 33014 Bad Driburg Bad Driburg Hildegundestraße 6 | N40: 01-03-05-0076-0004-BDrib-Kern | O40: Antonius Wiethaup | P40: towiethaup@web.de | Y40: Pendiente | Z40: Reprogramado
...

Sheet Dashboard Semanal
A1: DASHBOARD SEMANAL — CARGA Y CAPACIDAD
A2: Horario laboral: 08:00 - 17:00 | Capacidad: 2 técnicos = 4.5 unidades/día | 7 técnicos = 3 parejas + 1
A4: RESUMEN POR SEMANA
A5: Semana | B5: Rango Fechas | C5: Total Citas | D5: Total Unidades | E5: TK Máx. Req. | F5: Lunes | G5: Martes | H5: Miércoles | I5: Jueves | J5: Viernes | K5: WH | L5: WE
A6: S07 | B6: 2026-02-09 → 2026-02-13 | C6: 12 | D6: 76 | E6: 3 | F6: 4 | G6: 2 | H6: 2 | I6: 2 | J6: 2 | K6: 0 | L6: 76
A7: S08 | B7: 2026-02-16 → 2026-02-20 | C7: 14 | D7: 111 | E7: 4 | F7: 3 | G7: 3 | H7: 3 | I7: 2 | J7: 3 | K7: 0 | L7: 111
A8: S09 | B8: 2026-02-23 → 2026-02-27 | C8: 13 | D8: 62 | E8: 4 | F8: 3 | G8: 2 | H8: 3 | I8: 3 | J8: 2 | K8: 30 | L8: 32
A9: S10 | B9: 2026-03-02 → 2026-03-06 | C9: 9 | D9: 66 | E9: 4 | F9: 2 | G9: 2 | H9: 2 | I9: 2 | J9: 1 | K9: 17 | L9: 49
A10: S11 | B10: 2026-03-09 → 2026-03-13 | C10: 10 | D10: 51 | E10: 4 | F10: 2 | G10: 3 | H10: 2 | I10: 2 | J10: 1 | K10: 0 | L10: 51
A11: S12 | B11: 2026-03-16 → 2026-03-20 | C11: 7 | D11: 35 | E11: 4 | F11: 2 | G11: 1 | H11: 2 | I11: 1 | J11: 1 | K11: 3 | L11: 32
A12: S13 | B12: 2026-03-23 → 2026-03-27 | C12: 6 | D12: 28 | E12: 3 | F12: 2 | G12: 1 | H12: 1 | I12: 1 | J12: 1 | K12: 13 | L12: 15
A13: S14 | B13: 2026-03-30 → 2026-04-02 | C13: 5 | D13: 24 | E13: 3 | F13: 1 | G13: 2 | H13: 1 | I13: 1 | J13: 0 | K13: 0 | L13: 24
A14: S16 | B14: 2026-04-13 → 2026-04-13 | C14: 1 | D14: 4 | E14: 2 | F14: 1 | G14: 0 | H14: 0 | I14: 0 | J14: 0 | K14: 0 | L14: 4
A15: TOTAL | C15: =SUM(C6:C14) -> 77 | D15: =SUM(D6:D14) -> 457 | E15: =SUM(E6:E14) -> 31 | F15: =SUM(F6:F14) -> 20 | G15: =SUM(G6:G14) -> 16 | H15: =SUM(H6:H14) -> 16 | I15: =SUM(I6:I14) -> 14 | J15: =SUM(J6:J14) -> 11 | ... L15: =SUM(L6:L14) -> 394
A18: CAPACIDAD vs DEMANDA
A19: Semana | B19: Unidades Programadas | C19: Capacidad Semanal (67.5u) | D19: % Utilización | E19: TK Extra Necesarios | F19: Holgura (unidades)
A20: S07 | B20: 76 | C20: 67.5 | D20: =B20/C20 -> 1.1259259 | E20: =IF(B20>C20,ROUNDUP((B20-C20)/4.5/5*2,0),0) -> 1 | F20: =C20-B20 -> -8.5
A21: S08 | B21: 111 | C21: 67.5 | D21: =B21/C21 -> 1.6444444 | E21: =IF(B21>C21,ROUNDUP((B21-C21)/4.5/5*2,0),0) -> 4 | F21: =C21-B21 -> -43.5
A22: S09 | B22: 62 | C22: 67.5 | D22: =B22/C22 -> 0.91851852 | E22: =IF(B22>C22,ROUNDUP((B22-C22)/4.5/5*2,0),0) -> 0 | F22: =C22-B22 -> 5.5
A23: S10 | B23: 66 | C23: 67.5 | D23: =B23/C23 -> 0.97777778 | E23: =IF(B23>C23,ROUNDUP((B23-C23)/4.5/5*2,0),0) -> 0 | F23: =C23-B23 -> 1.5
A24: S11 | B24: 51 | C24: 67.5 | D24: =B24/C24 -> 0.75555556 | E24: =IF(B24>C24,ROUNDUP((B24-C24)/4.5/5*2,0),0) -> 0 | F24: =C24-B24 -> 16.5
A25: S12 | B25: 35 | C25: 67.5 | D25: =B25/C25 -> 0.51851852 | E25: =IF(B25>C25,ROUNDUP((B25-C25)/4.5/5*2,0),0) -> 0 | F25: =C25-B25 -> 32.5
A26: S13 | B26: 28 | C26: 67.5 | D26: =B26/C26 -> 0.41481481 | E26: =IF(B26>C26,ROUNDUP((B26-C26)/4.5/5*2,0),0) -> 0 | F26: =C26-B26 -> 39.5
A27: S14 | B27: 24 | C27: 67.5 | D27: =B27/C27 -> 0.35555556 | E27: =IF(B27>C27,ROUNDUP((B27-C27)/4.5/5*2,0),0) -> 0 | F27: =C27-B27 -> 43.5
A28: S16 | B28: 4 | C28: 67.5 | D28: =B28/C28 -> 0.059259259 | E28: =IF(B28>C28,ROUNDUP((B28-C28)/4.5/5*2,0),0) -> 0 | F28: =C28-B28 -> 63.5

Sheet Técnicos
A1: CARGA Y RENDIMIENTO POR TÉCNICO
A3: Fórmulas automáticas ← hoja 'Citas' columnas R-X. Asigne técnicos allí.
A5: Técnico | B5: Citas Asignadas | C5: Pendientes | D5: En Progreso | E5: Completadas | F5: Unidades Totales | G5: % Completado
A6: Alejandro Herrera | B6: =COUNTIF(Citas!R:R,A6)+COUNTIF(Citas!S:S,A6)+COUNTIF(Citas!T:T,A6)+COUNTIF(Citas!U:U,A6)+COUNTIF(Citas!V:V,A6)+COUNTIF(Citas!W:W,A6)+COUNTIF(Citas!X:X,A6) -> 0 | C6: =COUNTIFS(Citas!R:R,A6,Citas!Y:Y,"Pendiente")+COUNTIFS(Citas!S:S,A6,Citas!Y:Y,"Pendiente")+COUNTIFS(Citas!T:T,A6,Citas!Y:Y,"Pendiente")+COUNTIFS(Citas!U:U,A6,Citas!Y:Y,"Pendiente")+COUNTIFS(Citas!V:V,A6,Citas!Y:Y,"Pendiente")+COUNTIFS(Citas!W:W,A6,Citas!Y:Y,"Pendiente")+COUNTIFS(Citas!X:X,A6,Citas!Y:Y,"Pendiente") -> 0 | D6: =COUNTIFS(Citas!R:R,A6,Citas!Y:Y,"En Progreso")+COUNTIFS(Citas!S:S,A6,Citas!Y:Y,"En Progreso")+COUNTIFS(Citas!T:T,A6,Citas!Y:Y,"En Progreso")+COUNTIFS(Citas!U:U,A6,Citas!Y:Y,"En Progreso")+COUNTIFS(Citas!V:V,A6,Citas!Y:Y,"En Progreso")+COUNTIFS(Citas!W:W,A6,Citas!Y:Y,"En Progreso")+COUNTIFS(Citas!X:X,A6,Citas!Y:Y,"En Progreso") -> 0 | E6: =COUNTIFS(Citas!R:R,A6,Citas!Y:Y,"Completado")+COUNTIFS(Citas!S:S,A6,Citas!Y:Y,"Completado")+COUNTIFS(Citas!T:T,A6,Citas!Y:Y,"Completado")+COUNTIFS(Citas!U:U,A6,Citas!Y:Y,"Completado")+COUNTIFS(Citas!V:V,A6,Citas!Y:Y,"Completado")+COUNTIFS(Citas!W:W,A6,Citas!Y:Y,"Completado")+COUNTIFS(Citas!X:X,A6,Citas!Y:Y,"Completado") -> 0 | F6: =SUMPRODUCT((Citas!R$5:R$81=A6)*Citas!I$5:I$81)+SUMPRODUCT((Citas!S$5:S$81=A6)*Citas!I$5:I$81)+SUMPRODUCT((Citas!T$5:T$81=A6)*Citas!I$5:I$81)+SUMPRODUCT((Citas!U$5:U$81=A6)*Citas!I$5:I$81)+SUMPRODUCT((Citas!V$5:V$81=A6)*Citas!I$5:I$81)+SUMPRODUCT((Citas!W$5:W$81=A6)*Citas!I$5:I$81)+SUMPRODUCT((Citas!X$5:X$81=A6)*Citas!I$5:I$81) -> 0 | G6: =IF(B6>0,E6/B6,0) -> 0
A7: Alexander Herrera | B7: =COUNTIF(Citas!R:R,A7)+COUNTIF(Citas!S:S,A7)+COUNTIF(Citas!T:T,A7)+COUNTIF(Citas!U:U,A7)+COUNTIF(Citas!V:V,A7)+COUNTIF(Citas!W:W,A7)+COUNTIF(Citas!X:X,A7) -> 0 | C7: =COUNTIFS(Citas!R:R,A7,Citas!Y:Y,"Pendiente")+COUNTIFS(Citas!S:S,A7,Citas!Y:Y,"Pendiente")+COUNTIFS(Citas!T:T,A7,Citas!Y:Y,"Pendiente")+COUNTIFS(Citas!U:U,A7,Citas!Y:Y,"Pendiente")+COUNTIFS(Citas!V:V,A7,Citas!Y:Y,"Pendiente")+COUNTIFS(Citas!W:W,A7,Citas!Y:Y,"Pendiente")+COUNTIFS(Citas!X:X,A7,Citas!Y:Y,"Pendiente") -> 0 | D7: =COUNTIFS(Citas!R:R,A7,Citas!Y:Y,"En Progreso")+COUNTIFS(Citas!S:S,A7,Citas!Y:Y,"En Progreso")+COUNTIFS(Citas!T:T,A7,Citas!Y:Y,"En Progreso")+COUNTIFS(Citas!U:U,A7,Citas!Y:Y,"En Progreso")+COUNTIFS(Citas!V:V,A7,Citas!Y:Y,"En Progreso")+COUNTIFS(Citas!W:W,A7,Citas!Y:Y,"En Progreso")+COUNTIFS(Citas!X:X,A7,Citas!Y:Y,"En Progreso") -> 0 | E7: =COUNTIFS(Citas!R:R,A7,Citas!Y:Y,"Completado")+COUNTIFS(Citas!S:S,A7,Citas!Y:Y,"Completado")+COUNTIFS(Citas!T:T,A7,Citas!Y:Y,"Completado")+COUNTIFS(Citas!U:U,A7,Citas!Y:Y,"Completado")+COUNTIFS(Citas!V:V,A7,Citas!Y:Y,"Completado")+COUNTIFS(Citas!W:W,A7,Citas!Y:Y,"Completado")+COUNTIFS(Citas!X:X,A7,Citas!Y:Y,"Completado") -> 0 | F7: =SUMPRODUCT((Citas!R$5:R$81=A7)*Citas!I$5:I$81)+SUMPRODUCT((Citas!S$5:S$81=A7)*Citas!I$5:I$81)+SUMPRODUCT((Citas!T$5:T$81=A7)*Citas!I$5:I$81)+SUMPRODUCT((Citas!U$5:U$81=A7)*Citas!I$5:I$81)+SUMPRODUCT((Citas!V$5:V$81=A7)*Citas!I$5:I$81)+SUMPRODUCT((Citas!W$5:W$81=A7)*Citas!I$5:I$81)+SUMPRODUCT((Citas!X$5:X$81=A7)*Citas!I$5:I$81) -> 0 | G7: =IF(B7>0,E7/B7,0) -> 0
A8: Eddier Aladana | B8: =COUNTIF(Citas!R:R,A8)+COUNTIF(Citas!S:S,A8)+COUNTIF(Citas!T:T,A8)+COUNTIF(Citas!U:U,A8)+COUNTIF(Citas!V:V,A8)+COUNTIF(Citas!W:W,A8)+COUNTIF(Citas!X:X,A8) -> 0 | C8: =COUNTIFS(Citas!R:R,A8,Citas!Y:Y,"Pendiente")+COUNTIFS(Citas!S:S,A8,Citas!Y:Y,"Pendiente")+COUNTIFS(Citas!T:T,A8,Citas!Y:Y,"Pendiente")+COUNTIFS(Citas!U:U,A8,Citas!Y:Y,"Pendiente")+COUNTIFS(Citas!V:V,A8,Citas!Y:Y,"Pendiente")+COUNTIFS(Citas!W:W,A8,Citas!Y:Y,"Pendiente")+COUNTIFS(Citas!X:X,A8,Citas!Y:Y,"Pendiente") -> 0 | D8: =COUNTIFS(Citas!R:R,A8,Citas!Y:Y,"En Progreso")+COUNTIFS(Citas!S:S,A8,Citas!Y:Y,"En Progreso")+COUNTIFS(Citas!T:T,A8,Citas!Y:Y,"En Progreso")+COUNTIFS(Citas!U:U,A8,Citas!Y:Y,"En Progreso")+COUNTIFS(Citas!V:V,A8,Citas!Y:Y,"En Progreso")+COUNTIFS(Citas!W:W,A8,Citas!Y:Y,"En Progreso")+COUNTIFS(Citas!X:X,A8,Citas!Y:Y,"En Progreso") -> 0 | E8: =COUNTIFS(Citas!R:R,A8,Citas!Y:Y,"Completado")+COUNTIFS(Citas!S:S,A8,Citas!Y:Y,"Completado")+COUNTIFS(Citas!T:T,A8,Citas!Y:Y,"Completado")+COUNTIFS(Citas!U:U,A8,Citas!Y:Y,"Completado")+COUNTIFS(Citas!V:V,A8,Citas!Y:Y,"Completado")+COUNTIFS(Citas!W:W,A8,Citas!Y:Y,"Completado")+COUNTIFS(Citas!X:X,A8,Citas!Y:Y,"Completado") -> 0 | F8: =SUMPRODUCT((Citas!R$5:R$81=A8)*Citas!I$5:I$81)+SUMPRODUCT((Citas!S$5:S$81=A8)*Citas!I$5:I$81)+SUMPRODUCT((Citas!T$5:T$81=A8)*Citas!I$5:I$81)+SUMPRODUCT((Citas!U$5:U$81=A8)*Citas!I$5:I$81)+SUMPRODUCT((Citas!V$5:V$81=A8)*Citas!I$5:I$81)+SUMPRODUCT((Citas!W$5:W$81=A8)*Citas!I$5:I$81)+SUMPRODUCT((Citas!X$5:X$81=A8)*Citas!I$5:I$81) -> 0 | G8: =IF(B8>0,E8/B8,0) -> 0
A9: Contratista 1 | B9: =COUNTIF(Citas!R:R,A9)+COUNTIF(Citas!S:S,A9)+COUNTIF(Citas!T:T,A9)+COUNTIF(Citas!U:U,A9)+COUNTIF(Citas!V:V,A9)+COUNTIF(Citas!W:W,A9)+COUNTIF(Citas!X:X,A9) -> 0 | C9: =COUNTIFS(Citas!R:R,A9,Citas!Y:Y,"Pendiente")+COUNTIFS(Citas!S:S,A9,Citas!Y:Y,"Pendiente")+COUNTIFS(Citas!T:T,A9,Citas!Y:Y,"Pendiente")+COUNTIFS(Citas!U:U,A9,Citas!Y:Y,"Pendiente")+COUNTIFS(Citas!V:V,A9,Citas!Y:Y,"Pendiente")+COUNTIFS(Citas!W:W,A9,Citas!Y:Y,"Pendiente")+COUNTIFS(Citas!X:X,A9,Citas!Y:Y,"Pendiente") -> 0 | D9: =COUNTIFS(Citas!R:R,A9,Citas!Y:Y,"En Progreso")+COUNTIFS(Citas!S:S,A9,Citas!Y:Y,"En Progreso")+COUNTIFS(Citas!T:T,A9,Citas!Y:Y,"En Progreso")+COUNTIFS(Citas!U:U,A9,Citas!Y:Y,"En Progreso")+COUNTIFS(Citas!V:V,A9,Citas!Y:Y,"En Progreso")+COUNTIFS(Citas!W:W,A9,Citas!Y:Y,"En Progreso")+COUNTIFS(Citas!X:X,A9,Citas!Y:Y,"En Progreso") -> 0 | E9: =COUNTIFS(Citas!R:R,A9,Citas!Y:Y,"Completado")+COUNTIFS(Citas!S:S,A9,Citas!Y:Y,"Completado")+COUNTIFS(Citas!T:T,A9,Citas!Y:Y,"Completado")+COUNTIFS(Citas!U:U,A9,Citas!Y:Y,"Completado")+COUNTIFS(Citas!V:V,A9,Citas!Y:Y,"Completado")+COUNTIFS(Citas!W:W,A9,Citas!Y:Y,"Completado")+COUNTIFS(Citas!X:X,A9,Citas!Y:Y,"Completado") -> 0 | F9: =SUMPRODUCT((Citas!R$5:R$81=A9)*Citas!I$5:I$81)+SUMPRODUCT((Citas!S$5:S$81=A9)*Citas!I$5:I$81)+SUMPRODUCT((Citas!T$5:T$81=A9)*Citas!I$5:I$81)+SUMPRODUCT((Citas!U$5:U$81=A9)*Citas!I$5:I$81)+SUMPRODUCT((Citas!V$5:V$81=A9)*Citas!I$5:I$81)+SUMPRODUCT((Citas!W$5:W$81=A9)*Citas!I$5:I$81)+SUMPRODUCT((Citas!X$5:X$81=A9)*Citas!I$5:I$81) -> 0 | G9: =IF(B9>0,E9/B9,0) -> 0
A10: Contratista 2 | B10: =COUNTIF(Citas!R:R,A10)+COUNTIF(Citas!S:S,A10)+COUNTIF(Citas!T:T,A10)+COUNTIF(Citas!U:U,A10)+COUNTIF(Citas!V:V,A10)+COUNTIF(Citas!W:W,A10)+COUNTIF(Citas!X:X,A10) -> 0 | C10: =COUNTIFS(Citas!R:R,A10,Citas!Y:Y,"Pendiente")+COUNTIFS(Citas!S:S,A10,Citas!Y:Y,"Pendiente")+COUNTIFS(Citas!T:T,A10,Citas!Y:Y,"Pendiente")+COUNTIFS(Citas!U:U,A10,Citas!Y:Y,"Pendiente")+COUNTIFS(Citas!V:V,A10,Citas!Y:Y,"Pendiente")+COUNTIFS(Citas!W:W,A10,Citas!Y:Y,"Pendiente")+COUNTIFS(Citas!X:X,A10,Citas!Y:Y,"Pendiente") -> 0 | D10: =COUNTIFS(Citas!R:R,A10,Citas!Y:Y,"En Progreso")+COUNTIFS(Citas!S:S,A10,Citas!Y:Y,"En Progreso")+COUNTIFS(Citas!T:T,A10,Citas!Y:Y,"En Progreso")+COUNTIFS(Citas!U:U,A10,Citas!Y:Y,"En Progreso")+COUNTIFS(Citas!V:V,A10,Citas!Y:Y,"En Progreso")+COUNTIFS(Citas!W:W,A10,Citas!Y:Y,"En Progreso")+COUNTIFS(Citas!X:X,A10,Citas!Y:Y,"En Progreso") -> 0 | E10: =COUNTIFS(Citas!R:R,A10,Citas!Y:Y,"Completado")+COUNTIFS(Citas!S:S,A10,Citas!Y:Y,"Completado")+COUNTIFS(Citas!T:T,A10,Citas!Y:Y,"Completado")+COUNTIFS(Citas!U:U,A10,Citas!Y:Y,"Completado")+COUNTIFS(Citas!V:V,A10,Citas!Y:Y,"Completado")+COUNTIFS(Citas!W:W,A10,Citas!Y:Y,"Completado")+COUNTIFS(Citas!X:X,A10,Citas!Y:Y,"Completado") -> 0 | F10: =SUMPRODUCT((Citas!R$5:R$81=A10)*Citas!I$5:I$81)+SUMPRODUCT((Citas!S$5:S$81=A10)*Citas!I$5:I$81)+SUMPRODUCT((Citas!T$5:T$81=A10)*Citas!I$5:I$81)+SUMPRODUCT((Citas!U$5:U$81=A10)*Citas!I$5:I$81)+SUMPRODUCT((Citas!V$5:V$81=A10)*Citas!I$5:I$81)+SUMPRODUCT((Citas!W$5:W$81=A10)*Citas!I$5:I$81)+SUMPRODUCT((Citas!X$5:X$81=A10)*Citas!I$5:I$81) -> 0 | G10: =IF(B10>0,E10/B10,0) -> 0
A11: Contratista 3 | B11: =COUNTIF(Citas!R:R,A11)+COUNTIF(Citas!S:S,A11)+COUNTIF(Citas!T:T,A11)+COUNTIF(Citas!U:U,A11)+COUNTIF(Citas!V:V,A11)+COUNTIF(Citas!W:W,A11)+COUNTIF(Citas!X:X,A11) -> 0 | C11: =COUNTIFS(Citas!R:R,A11,Citas!Y:Y,"Pendiente")+COUNTIFS(Citas!S:S,A11,Citas!Y:Y,"Pendiente")+COUNTIFS(Citas!T:T,A11,Citas!Y:Y,"Pendiente")+COUNTIFS(Citas!U:U,A11,Citas!Y:Y,"Pendiente")+COUNTIFS(Citas!V:V,A11,Citas!Y:Y,"Pendiente")+COUNTIFS(Citas!W:W,A11,Citas!Y:Y,"Pendiente")+COUNTIFS(Citas!X:X,A11,Citas!Y:Y,"Pendiente") -> 0 | D11: =COUNTIFS(Citas!R:R,A11,Citas!Y:Y,"En Progreso")+COUNTIFS(Citas!S:S,A11,Citas!Y:Y,"En Progreso")+COUNTIFS(Citas!T:T,A11,Citas!Y:Y,"En Progreso")+COUNTIFS(Citas!U:U,A11,Citas!Y:Y,"En Progreso")+COUNTIFS(Citas!V:V,A11,Citas!Y:Y,"En Progreso")+COUNTIFS(Citas!W:W,A11,Citas!Y:Y,"En Progreso")+COUNTIFS(Citas!X:X,A11,Citas!Y:Y,"En Progreso") -> 0 | E11: =COUNTIFS(Citas!R:R,A11,Citas!Y:Y,"Completado")+COUNTIFS(Citas!S:S,A11,Citas!Y:Y,"Completado")+COUNTIFS(Citas!T:T,A11,Citas!Y:Y,"Completado")+COUNTIFS(Citas!U:U,A11,Citas!Y:Y,"Completado")+COUNTIFS(Citas!V:V,A11,Citas!Y:Y,"Completado")+COUNTIFS(Citas!W:W,A11,Citas!Y:Y,"Completado")+COUNTIFS(Citas!X:X,A11,Citas!Y:Y,"Completado") -> 0 | F11: =SUMPRODUCT((Citas!R$5:R$81=A11)*Citas!I$5:I$81)+SUMPRODUCT((Citas!S$5:S$81=A11)*Citas!I$5:I$81)+SUMPRODUCT((Citas!T$5:T$81=A11)*Citas!I$5:I$81)+SUMPRODUCT((Citas!U$5:U$81=A11)*Citas!I$5:I$81)+SUMPRODUCT((Citas!V$5:V$81=A11)*Citas!I$5:I$81)+SUMPRODUCT((Citas!W$5:W$81=A11)*Citas!I$5:I$81)+SUMPRODUCT((Citas!X$5:X$81=A11)*Citas!I$5:I$81) -> 0 | G11: =IF(B11>0,E11/B11,0) -> 0
A12: Juan Correa | B12: =COUNTIF(Citas!R:R,A12)+COUNTIF(Citas!S:S,A12)+COUNTIF(Citas!T:T,A12)+COUNTIF(Citas!U:U,A12)+COUNTIF(Citas!V:V,A12)+COUNTIF(Citas!W:W,A12)+COUNTIF(Citas!X:X,A12) -> 0 | C12: =COUNTIFS(Citas!R:R,A12,Citas!Y:Y,"Pendiente")+COUNTIFS(Citas!S:S,A12,Citas!Y:Y,"Pendiente")+COUNTIFS(Citas!T:T,A12,Citas!Y:Y,"Pendiente")+COUNTIFS(Citas!U:U,A12,Citas!Y:Y,"Pendiente")+COUNTIFS(Citas!V:V,A12,Citas!Y:Y,"Pendiente")+COUNTIFS(Citas!W:W,A12,Citas!Y:Y,"Pendiente")+COUNTIFS(Citas!X:X,A12,Citas!Y:Y,"Pendiente") -> 0 | D12: =COUNTIFS(Citas!R:R,A12,Citas!Y:Y,"En Progreso")+COUNTIFS(Citas!S:S,A12,Citas!Y:Y,"En Progreso")+COUNTIFS(Citas!T:T,A12,Citas!Y:Y,"En Progreso")+COUNTIFS(Citas!U:U,A12,Citas!Y:Y,"En Progreso")+COUNTIFS(Citas!V:V,A12,Citas!Y:Y,"En Progreso")+COUNTIFS(Citas!W:W,A12,Citas!Y:Y,"En Progreso")+COUNTIFS(Citas!X:X,A12,Citas!Y:Y,"En Progreso") -> 0 | E12: =COUNTIFS(Citas!R:R,A12,Citas!Y:Y,"Completado")+COUNTIFS(Citas!S:S,A12,Citas!Y:Y,"Completado")+COUNTIFS(Citas!T:T,A12,Citas!Y:Y,"Completado")+COUNTIFS(Citas!U:U,A12,Citas!Y:Y,"Completado")+COUNTIFS(Citas!V:V,A12,Citas!Y:Y,"Completado")+COUNTIFS(Citas!W:W,A12,Citas!Y:Y,"Completado")+COUNTIFS(Citas!X:X,A12,Citas!Y:Y,"Completado") -> 0 | F12: =SUMPRODUCT((Citas!R$5:R$81=A12)*Citas!I$5:I$81)+SUMPRODUCT((Citas!S$5:S$81=A12)*Citas!I$5:I$81)+SUMPRODUCT((Citas!T$5:T$81=A12)*Citas!I$5:I$81)+SUMPRODUCT((Citas!U$5:U$81=A12)*Citas!I$5:I$81)+SUMPRODUCT((Citas!V$5:V$81=A12)*Citas!I$5:I$81)+SUMPRODUCT((Citas!W$5:W$81=A12)*Citas!I$5:I$81)+SUMPRODUCT((Citas!X$5:X$81=A12)*Citas!I$5:I$81) -> 0 | G12: =IF(B12>0,E12/B12,0) -> 0
A13: TOTAL | B13: =SUM(B6:B12) -> 0 | C13: =SUM(C6:C12) -> 0 | D13: =SUM(D6:D12) -> 0 | E13: =SUM(E6:E12) -> 0 | F13: =SUM(F6:F12) -> 0 | G13: =IF(B13>0,E13/B13,0) -> 0
A16: CARGA SEMANAL POR TÉCNICO
A17: Técnico | B17: S07 | C17: S08 | D17: S09 | E17: S10 | F17: S11 | G17: S12 | H17: S13 | I17: S14 | J17: S16
A18: Alejandro Herrera | B18: =COUNTIFS(Citas!R:R,$A18,Citas!A:A,"S07")+COUNTIFS(Citas!S:S,$A18,Citas!A:A,"S07")+COUNTIFS(Citas!T:T,$A18,Citas!A:A,"S07")+COUNTIFS(Citas!U:U,$A18,Citas!A:A,"S07")+COUNTIFS(Citas!V:V,$A18,Citas!A:A,"S07")+COUNTIFS(Citas!W:W,$A18,Citas!A:A,"S07")+COUNTIFS(Citas!X:X,$A18,Citas!A:A,"S07") -> 0 | C18: =COUNTIFS(Citas!R:R,$A18,Citas!A:A,"S08")+COUNTIFS(Citas!S:S,$A18,Citas!A:A,"S08")+COUNTIFS(Citas!T:T,$A18,Citas!A:A,"S08")+COUNTIFS(Citas!U:U,$A18,Citas!A:A,"S08")+COUNTIFS(Citas!V:V,$A18,Citas!A:A,"S08")+COUNTIFS(Citas!W:W,$A18,Citas!A:A,"S08")+COUNTIFS(Citas!X:X,$A18,Citas!A:A,"S08") -> 0 | D18: =COUNTIFS(Citas!R:R,$A18,Citas!A:A,"S09")+COUNTIFS(Citas!S:S,$A18,Citas!A:A,"S09")+COUNTIFS(Citas!T:T,$A18,Citas!A:A,"S09")+COUNTIFS(Citas!U:U,$A18,Citas!A:A,"S09")+COUNTIFS(Citas!V:V,$A18,Citas!A:A,"S09")+COUNTIFS(Citas!W:W,$A18,Citas!A:A,"S09")+COUNTIFS(Citas!X:X,$A18,Citas!A:A,"S09") -> 0 | E18: =COUNTIFS(Citas!R:R,$A18,Citas!A:A,"S10")+COUNTIFS(Citas!S:S,$A18,Citas!A:A,"S10")+COUNTIFS(Citas!T:T,$A18,Citas!A:A,"S10")+COUNTIFS(Citas!U:U,$A18,Citas!A:A,"S10")+COUNTIFS(Citas!V:V,$A18,Citas!A:A,"S10")+COUNTIFS(Citas!W:W,$A18,Citas!A:A,"S10")+COUNTIFS(Citas!X:X,$A18,Citas!A:A,"S10") -> 0 | F18: =COUNTIFS(Citas!R:R,$A18,Citas!A:A,"S11")+COUNTIFS(Citas!S:S,$A18,Citas!A:A,"S11")+COUNTIFS(Citas!T:T,$A18,Citas!A:A,"S11")+COUNTIFS(Citas!U:U,$A18,Citas!A:A,"S11")+COUNTIFS(Citas!V:V,$A18,Citas!A:A,"S11")+COUNTIFS(Citas!W:W,$A18,Citas!A:A,"S11")+COUNTIFS(Citas!X:X,$A18,Citas!A:A,"S11") -> 0 | G18: =COUNTIFS(Citas!R:R,$A18,Citas!A:A,"S12")+COUNTIFS(Citas!S:S,$A18,Citas!A:A,"S12")+COUNTIFS(Citas!T:T,$A18,Citas!A:A,"S12")+COUNTIFS(Citas!U:U,$A18,Citas!A:A,"S12")+COUNTIFS(Citas!V:V,$A18,Citas!A:A,"S12")+COUNTIFS(Citas!W:W,$A18,Citas!A:A,"S12")+COUNTIFS(Citas!X:X,$A18,Citas!A:A,"S12") -> 0 | H18: =COUNTIFS(Citas!R:R,$A18,Citas!A:A,"S13")+COUNTIFS(Citas!S:S,$A18,Citas!A:A,"S13")+COUNTIFS(Citas!T:T,$A18,Citas!A:A,"S13")+COUNTIFS(Citas!U:U,$A18,Citas!A:A,"S13")+COUNTIFS(Citas!V:V,$A18,Citas!A:A,"S13")+COUNTIFS(Citas!W:W,$A18,Citas!A:A,"S13")+COUNTIFS(Citas!X:X,$A18,Citas!A:A,"S13") -> 0 | I18: =COUNTIFS(Citas!R:R,$A18,Citas!A:A,"S14")+COUNTIFS(Citas!S:S,$A18,Citas!A:A,"S14")+COUNTIFS(Citas!T:T,$A18,Citas!A:A,"S14")+COUNTIFS(Citas!U:U,$A18,Citas!A:A,"S14")+COUNTIFS(Citas!V:V,$A18,Citas!A:A,"S14")+COUNTIFS(Citas!W:W,$A18,Citas!A:A,"S14")+COUNTIFS(Citas!X:X,$A18,Citas!A:A,"S14") -> 0 | J18: =COUNTIFS(Citas!R:R,$A18,Citas!A:A,"S16")+COUNTIFS(Citas!S:S,$A18,Citas!A:A,"S16")+COUNTIFS(Citas!T:T,$A18,Citas!A:A,"S16")+COUNTIFS(Citas!U:U,$A18,Citas!A:A,"S16")+COUNTIFS(Citas!V:V,$A18,Citas!A:A,"S16")+COUNTIFS(Citas!W:W,$A18,Citas!A:A,"S16")+COUNTIFS(Citas!X:X,$A18,Citas!A:A,"S16") -> 0
A19: Alexander Herrera | B19: =COUNTIFS(Citas!R:R,$A19,Citas!A:A,"S07")+COUNTIFS(Citas!S:S,$A19,Citas!A:A,"S07")+COUNTIFS(Citas!T:T,$A19,Citas!A:A,"S07")+COUNTIFS(Citas!U:U,$A19,Citas!A:A,"S07")+COUNTIFS(Citas!V:V,$A19,Citas!A:A,"S07")+COUNTIFS(Citas!W:W,$A19,Citas!A:A,"S07")+COUNTIFS(Citas!X:X,$A19,Citas!A:A,"S07") -> 0 | C19: =COUNTIFS(Citas!R:R,$A19,Citas!A:A,"S08")+COUNTIFS(Citas!S:S,$A19,Citas!A:A,"S08")+COUNTIFS(Citas!T:T,$A19,Citas!A:A,"S08")+COUNTIFS(Citas!U:U,$A19,Citas!A:A,"S08")+COUNTIFS(Citas!V:V,$A19,Citas!A:A,"S08")+COUNTIFS(Citas!W:W,$A19,Citas!A:A,"S08")+COUNTIFS(Citas!X:X,$A19,Citas!A:A,"S08") -> 0 | D19: =COUNTIFS(Citas!R:R,$A19,Citas!A:A,"S09")+COUNTIFS(Citas!S:S,$A19,Citas!A:A,"S09")+COUNTIFS(Citas!T:T,$A19,Citas!A:A,"S09")+COUNTIFS(Citas!U:U,$A19,Citas!A:A,"S09")+COUNTIFS(Citas!V:V,$A19,Citas!A:A,"S09")+COUNTIFS(Citas!W:W,$A19,Citas!A:A,"S09")+COUNTIFS(Citas!X:X,$A19,Citas!A:A,"S09") -> 0 | E19: =COUNTIFS(Citas!R:R,$A19,Citas!A:A,"S10")+COUNTIFS(Citas!S:S,$A19,Citas!A:A,"S10")+COUNTIFS(Citas!T:T,$A19,Citas!A:A,"S10")+COUNTIFS(Citas!U:U,$A19,Citas!A:A,"S10")+COUNTIFS(Citas!V:V,$A19,Citas!A:A,"S10")+COUNTIFS(Citas!W:W,$A19,Citas!A:A,"S10")+COUNTIFS(Citas!X:X,$A19,Citas!A:A,"S10") -> 0 | F19: =COUNTIFS(Citas!R:R,$A19,Citas!A:A,"S11")+COUNTIFS(Citas!S:S,$A19,Citas!A:A,"S11")+COUNTIFS(Citas!T:T,$A19,Citas!A:A,"S11")+COUNTIFS(Citas!U:U,$A19,Citas!A:A,"S11")+COUNTIFS(Citas!V:V,$A19,Citas!A:A,"S11")+COUNTIFS(Citas!W:W,$A19,Citas!A:A,"S11")+COUNTIFS(Citas!X:X,$A19,Citas!A:A,"S11") -> 0 | G19: =COUNTIFS(Citas!R:R,$A19,Citas!A:A,"S12")+COUNTIFS(Citas!S:S,$A19,Citas!A:A,"S12")+COUNTIFS(Citas!T:T,$A19,Citas!A:A,"S12")+COUNTIFS(Citas!U:U,$A19,Citas!A:A,"S12")+COUNTIFS(Citas!V:V,$A19,Citas!A:A,"S12")+COUNTIFS(Citas!W:W,$A19,Citas!A:A,"S12")+COUNTIFS(Citas!X:X,$A19,Citas!A:A,"S12") -> 0 | H19: =COUNTIFS(Citas!R:R,$A19,Citas!A:A,"S13")+COUNTIFS(Citas!S:S,$A19,Citas!A:A,"S13")+COUNTIFS(Citas!T:T,$A19,Citas!A:A,"S13")+COUNTIFS(Citas!U:U,$A19,Citas!A:A,"S13")+COUNTIFS(Citas!V:V,$A19,Citas!A:A,"S13")+COUNTIFS(Citas!W:W,$A19,Citas!A:A,"S13")+COUNTIFS(Citas!X:X,$A19,Citas!A:A,"S13") -> 0 | I19: =COUNTIFS(Citas!R:R,$A19,Citas!A:A,"S14")+COUNTIFS(Citas!S:S,$A19,Citas!A:A,"S14")+COUNTIFS(Citas!T:T,$A19,Citas!A:A,"S14")+COUNTIFS(Citas!U:U,$A19,Citas!A:A,"S14")+COUNTIFS(Citas!V:V,$A19,Citas!A:A,"S14")+COUNTIFS(Citas!W:W,$A19,Citas!A:A,"S14")+COUNTIFS(Citas!X:X,$A19,Citas!A:A,"S14") -> 0 | J19: =COUNTIFS(Citas!R:R,$A19,Citas!A:A,"S16")+COUNTIFS(Citas!S:S,$A19,Citas!A:A,"S16")+COUNTIFS(Citas!T:T,$A19,Citas!A:A,"S16")+COUNTIFS(Citas!U:U,$A19,Citas!A:A,"S16")+COUNTIFS(Citas!V:V,$A19,Citas!A:A,"S16")+COUNTIFS(Citas!W:W,$A19,Citas!A:A,"S16")+COUNTIFS(Citas!X:X,$A19,Citas!A:A,"S16") -> 0
A20: Eddier Aladana | B20: =COUNTIFS(Citas!R:R,$A20,Citas!A:A,"S07")+COUNTIFS(Citas!S:S,$A20,Citas!A:A,"S07")+COUNTIFS(Citas!T:T,$A20,Citas!A:A,"S07")+COUNTIFS(Citas!U:U,$A20,Citas!A:A,"S07")+COUNTIFS(Citas!V:V,$A20,Citas!A:A,"S07")+COUNTIFS(Citas!W:W,$A20,Citas!A:A,"S07")+COUNTIFS(Citas!X:X,$A20,Citas!A:A,"S07") -> 0 | C20: =COUNTIFS(Citas!R:R,$A20,Citas!A:A,"S08")+COUNTIFS(Citas!S:S,$A20,Citas!A:A,"S08")+COUNTIFS(Citas!T:T,$A20,Citas!A:A,"S08")+COUNTIFS(Citas!U:U,$A20,Citas!A:A,"S08")+COUNTIFS(Citas!V:V,$A20,Citas!A:A,"S08")+COUNTIFS(Citas!W:W,$A20,Citas!A:A,"S08")+COUNTIFS(Citas!X:X,$A20,Citas!A:A,"S08") -> 0 | D20: =COUNTIFS(Citas!R:R,$A20,Citas!A:A,"S09")+COUNTIFS(Citas!S:S,$A20,Citas!A:A,"S09")+COUNTIFS(Citas!T:T,$A20,Citas!A:A,"S09")+COUNTIFS(Citas!U:U,$A20,Citas!A:A,"S09")+COUNTIFS(Citas!V:V,$A20,Citas!A:A,"S09")+COUNTIFS(Citas!W:W,$A20,Citas!A:A,"S09")+COUNTIFS(Citas!X:X,$A20,Citas!A:A,"S09") -> 0 | E20: =COUNTIFS(Citas!R:R,$A20,Citas!A:A,"S10")+COUNTIFS(Citas!S:S,$A20,Citas!A:A,"S10")+COUNTIFS(Citas!T:T,$A20,Citas!A:A,"S10")+COUNTIFS(Citas!U:U,$A20,Citas!A:A,"S10")+COUNTIFS(Citas!V:V,$A20,Citas!A:A,"S10")+COUNTIFS(Citas!W:W,$A20,Citas!A:A,"S10")+COUNTIFS(Citas!X:X,$A20,Citas!A:A,"S10") -> 0 | F20: =COUNTIFS(Citas!R:R,$A20,Citas!A:A,"S11")+COUNTIFS(Citas!S:S,$A20,Citas!A:A,"S11")+COUNTIFS(Citas!T:T,$A20,Citas!A:A,"S11")+COUNTIFS(Citas!U:U,$A20,Citas!A:A,"S11")+COUNTIFS(Citas!V:V,$A20,Citas!A:A,"S11")+COUNTIFS(Citas!W:W,$A20,Citas!A:A,"S11")+COUNTIFS(Citas!X:X,$A20,Citas!A:A,"S11") -> 0 | G20: =COUNTIFS(Citas!R:R,$A20,Citas!A:A,"S12")+COUNTIFS(Citas!S:S,$A20,Citas!A:A,"S12")+COUNTIFS(Citas!T:T,$A20,Citas!A:A,"S12")+COUNTIFS(Citas!U:U,$A20,Citas!A:A,"S12")+COUNTIFS(Citas!V:V,$A20,Citas!A:A,"S12")+COUNTIFS(Citas!W:W,$A20,Citas!A:A,"S12")+COUNTIFS(Citas!X:X,$A20,Citas!A:A,"S12") -> 0 | H20: =COUNTIFS(Citas!R:R,$A20,Citas!A:A,"S13")+COUNTIFS(Citas!S:S,$A20,Citas!A:A,"S13")+COUNTIFS(Citas!T:T,$A20,Citas!A:A,"S13")+COUNTIFS(Citas!U:U,$A20,Citas!A:A,"S13")+COUNTIFS(Citas!V:V,$A20,Citas!A:A,"S13")+COUNTIFS(Citas!W:W,$A20,Citas!A:A,"S13")+COUNTIFS(Citas!X:X,$A20,Citas!A:A,"S13") -> 0 | I20: =COUNTIFS(Citas!R:R,$A20,Citas!A:A,"S14")+COUNTIFS(Citas!S:S,$A20,Citas!A:A,"S14")+COUNTIFS(Citas!T:T,$A20,Citas!A:A,"S14")+COUNTIFS(Citas!U:U,$A20,Citas!A:A,"S14")+COUNTIFS(Citas!V:V,$A20,Citas!A:A,"S14")+COUNTIFS(Citas!W:W,$A20,Citas!A:A,"S14")+COUNTIFS(Citas!X:X,$A20,Citas!A:A,"S14") -> 0 | J20: =COUNTIFS(Citas!R:R,$A20,Citas!A:A,"S16")+COUNTIFS(Citas!S:S,$A20,Citas!A:A,"S16")+COUNTIFS(Citas!T:T,$A20,Citas!A:A,"S16")+COUNTIFS(Citas!U:U,$A20,Citas!A:A,"S16")+COUNTIFS(Citas!V:V,$A20,Citas!A:A,"S16")+COUNTIFS(Citas!W:W,$A20,Citas!A:A,"S16")+COUNTIFS(Citas!X:X,$A20,Citas!A:A,"S16") -> 0
A21: Michel Matos | B21: =COUNTIFS(Citas!R:R,$A21,Citas!A:A,"S07")+COUNTIFS(Citas!S:S,$A21,Citas!A:A,"S07")+COUNTIFS(Citas!T:T,$A21,Citas!A:A,"S07")+COUNTIFS(Citas!U:U,$A21,Citas!A:A,"S07")+COUNTIFS(Citas!V:V,$A21,Citas!A:A,"S07")+COUNTIFS(Citas!W:W,$A21,Citas!A:A,"S07")+COUNTIFS(Citas!X:X,$A21,Citas!A:A,"S07") -> 0 | C21: =COUNTIFS(Citas!R:R,$A21,Citas!A:A,"S08")+COUNTIFS(Citas!S:S,$A21,Citas!A:A,"S08")+COUNTIFS(Citas!T:T,$A21,Citas!A:A,"S08")+COUNTIFS(Citas!U:U,$A21,Citas!A:A,"S08")+COUNTIFS(Citas!V:V,$A21,Citas!A:A,"S08")+COUNTIFS(Citas!W:W,$A21,Citas!A:A,"S08")+COUNTIFS(Citas!X:X,$A21,Citas!A:A,"S08") -> 0 | D21: =COUNTIFS(Citas!R:R,$A21,Citas!A:A,"S09")+COUNTIFS(Citas!S:S,$A21,Citas!A:A,"S09")+COUNTIFS(Citas!T:T,$A21,Citas!A:A,"S09")+COUNTIFS(Citas!U:U,$A21,Citas!A:A,"S09")+COUNTIFS(Citas!V:V,$A21,Citas!A:A,"S09")+COUNTIFS(Citas!W:W,$A21,Citas!A:A,"S09")+COUNTIFS(Citas!X:X,$A21,Citas!A:A,"S09") -> 0 | E21: =COUNTIFS(Citas!R:R,$A21,Citas!A:A,"S10")+COUNTIFS(Citas!S:S,$A21,Citas!A:A,"S10")+COUNTIFS(Citas!T:T,$A21,Citas!A:A,"S10")+COUNTIFS(Citas!U:U,$A21,Citas!A:A,"S10")+COUNTIFS(Citas!V:V,$A21,Citas!A:A,"S10")+COUNTIFS(Citas!W:W,$A21,Citas!A:A,"S10")+COUNTIFS(Citas!X:X,$A21,Citas!A:A,"S10") -> 0 | F21: =COUNTIFS(Citas!R:R,$A21,Citas!A:A,"S11")+COUNTIFS(Citas!S:S,$A21,Citas!A:A,"S11")+COUNTIFS(Citas!T:T,$A21,Citas!A:A,"S11")+COUNTIFS(Citas!U:U,$A21,Citas!A:A,"S11")+COUNTIFS(Citas!V:V,$A21,Citas!A:A,"S11")+COUNTIFS(Citas!W:W,$A21,Citas!A:A,"S11")+COUNTIFS(Citas!X:X,$A21,Citas!A:A,"S11") -> 0 | G21: =COUNTIFS(Citas!R:R,$A21,Citas!A:A,"S12")+COUNTIFS(Citas!S:S,$A21,Citas!A:A,"S12")+COUNTIFS(Citas!T:T,$A21,Citas!A:A,"S12")+COUNTIFS(Citas!U:U,$A21,Citas!A:A,"S12")+COUNTIFS(Citas!V:V,$A21,Citas!A:A,"S12")+COUNTIFS(Citas!W:W,$A21,Citas!A:A,"S12")+COUNTIFS(Citas!X:X,$A21,Citas!A:A,"S12") -> 0 | H21: =COUNTIFS(Citas!R:R,$A21,Citas!A:A,"S13")+COUNTIFS(Citas!S:S,$A21,Citas!A:A,"S13")+COUNTIFS(Citas!T:T,$A21,Citas!A:A,"S13")+COUNTIFS(Citas!U:U,$A21,Citas!A:A,"S13")+COUNTIFS(Citas!V:V,$A21,Citas!A:A,"S13")+COUNTIFS(Citas!W:W,$A21,Citas!A:A,"S13")+COUNTIFS(Citas!X:X,$A21,Citas!A:A,"S13") -> 0 | I21: =COUNTIFS(Citas!R:R,$A21,Citas!A:A,"S14")+COUNTIFS(Citas!S:S,$A21,Citas!A:A,"S14")+COUNTIFS(Citas!T:T,$A21,Citas!A:A,"S14")+COUNTIFS(Citas!U:U,$A21,Citas!A:A,"S14")+COUNTIFS(Citas!V:V,$A21,Citas!A:A,"S14")+COUNTIFS(Citas!W:W,$A21,Citas!A:A,"S14")+COUNTIFS(Citas!X:X,$A21,Citas!A:A,"S14") -> 0 | J21: =COUNTIFS(Citas!R:R,$A21,Citas!A:A,"S16")+COUNTIFS(Citas!S:S,$A21,Citas!A:A,"S16")+COUNTIFS(Citas!T:T,$A21,Citas!A:A,"S16")+COUNTIFS(Citas!U:U,$A21,Citas!A:A,"S16")+COUNTIFS(Citas!V:V,$A21,Citas!A:A,"S16")+COUNTIFS(Citas!W:W,$A21,Citas!A:A,"S16")+COUNTIFS(Citas!X:X,$A21,Citas!A:A,"S16") -> 0
A22: Alejandro Matos | B22: =COUNTIFS(Citas!R:R,$A22,Citas!A:A,"S07")+COUNTIFS(Citas!S:S,$A22,Citas!A:A,"S07")+COUNTIFS(Citas!T:T,$A22,Citas!A:A,"S07")+COUNTIFS(Citas!U:U,$A22,Citas!A:A,"S07")+COUNTIFS(Citas!V:V,$A22,Citas!A:A,"S07")+COUNTIFS(Citas!W:W,$A22,Citas!A:A,"S07")+COUNTIFS(Citas!X:X,$A22,Citas!A:A,"S07") -> 0 | C22: =COUNTIFS(Citas!R:R,$A22,Citas!A:A,"S08")+COUNTIFS(Citas!S:S,$A22,Citas!A:A,"S08")+COUNTIFS(Citas!T:T,$A22,Citas!A:A,"S08")+COUNTIFS(Citas!U:U,$A22,Citas!A:A,"S08")+COUNTIFS(Citas!V:V,$A22,Citas!A:A,"S08")+COUNTIFS(Citas!W:W,$A22,Citas!A:A,"S08")+COUNTIFS(Citas!X:X,$A22,Citas!A:A,"S08") -> 0 | D22: =COUNTIFS(Citas!R:R,$A22,Citas!A:A,"S09")+COUNTIFS(Citas!S:S,$A22,Citas!A:A,"S09")+COUNTIFS(Citas!T:T,$A22,Citas!A:A,"S09")+COUNTIFS(Citas!U:U,$A22,Citas!A:A,"S09")+COUNTIFS(Citas!V:V,$A22,Citas!A:A,"S09")+COUNTIFS(Citas!W:W,$A22,Citas!A:A,"S09")+COUNTIFS(Citas!X:X,$A22,Citas!A:A,"S09") -> 0 | E22: =COUNTIFS(Citas!R:R,$A22,Citas!A:A,"S10")+COUNTIFS(Citas!S:S,$A22,Citas!A:A,"S10")+COUNTIFS(Citas!T:T,$A22,Citas!A:A,"S10")+COUNTIFS(Citas!U:U,$A22,Citas!A:A,"S10")+COUNTIFS(Citas!V:V,$A22,Citas!A:A,"S10")+COUNTIFS(Citas!W:W,$A22,Citas!A:A,"S10")+COUNTIFS(Citas!X:X,$A22,Citas!A:A,"S10") -> 0 | F22: =COUNTIFS(Citas!R:R,$A22,Citas!A:A,"S11")+COUNTIFS(Citas!S:S,$A22,Citas!A:A,"S11")+COUNTIFS(Citas!T:T,$A22,Citas!A:A,"S11")+COUNTIFS(Citas!U:U,$A22,Citas!A:A,"S11")+COUNTIFS(Citas!V:V,$A22,Citas!A:A,"S11")+COUNTIFS(Citas!W:W,$A22,Citas!A:A,"S11")+COUNTIFS(Citas!X:X,$A22,Citas!A:A,"S11") -> 0 | G22: =COUNTIFS(Citas!R:R,$A22,Citas!A:A,"S12")+COUNTIFS(Citas!S:S,$A22,Citas!A:A,"S12")+COUNTIFS(Citas!T:T,$A22,Citas!A:A,"S12")+COUNTIFS(Citas!U:U,$A22,Citas!A:A,"S12")+COUNTIFS(Citas!V:V,$A22,Citas!A:A,"S12")+COUNTIFS(Citas!W:W,$A22,Citas!A:A,"S12")+COUNTIFS(Citas!X:X,$A22,Citas!A:A,"S12") -> 0 | H22: =COUNTIFS(Citas!R:R,$A22,Citas!A:A,"S13")+COUNTIFS(Citas!S:S,$A22,Citas!A:A,"S13")+COUNTIFS(Citas!T:T,$A22,Citas!A:A,"S13")+COUNTIFS(Citas!U:U,$A22,Citas!A:A,"S13")+COUNTIFS(Citas!V:V,$A22,Citas!A:A,"S13")+COUNTIFS(Citas!W:W,$A22,Citas!A:A,"S13")+COUNTIFS(Citas!X:X,$A22,Citas!A:A,"S13") -> 0 | I22: =COUNTIFS(Citas!R:R,$A22,Citas!A:A,"S14")+COUNTIFS(Citas!S:S,$A22,Citas!A:A,"S14")+COUNTIFS(Citas!T:T,$A22,Citas!A:A,"S14")+COUNTIFS(Citas!U:U,$A22,Citas!A:A,"S14")+COUNTIFS(Citas!V:V,$A22,Citas!A:A,"S14")+COUNTIFS(Citas!W:W,$A22,Citas!A:A,"S14")+COUNTIFS(Citas!X:X,$A22,Citas!A:A,"S14") -> 0 | J22: =COUNTIFS(Citas!R:R,$A22,Citas!A:A,"S16")+COUNTIFS(Citas!S:S,$A22,Citas!A:A,"S16")+COUNTIFS(Citas!T:T,$A22,Citas!A:A,"S16")+COUNTIFS(Citas!U:U,$A22,Citas!A:A,"S16")+COUNTIFS(Citas!V:V,$A22,Citas!A:A,"S16")+COUNTIFS(Citas!W:W,$A22,Citas!A:A,"S16")+COUNTIFS(Citas!X:X,$A22,Citas!A:A,"S16") -> 0
A23: Esteban Matos | B23: =COUNTIFS(Citas!R:R,$A23,Citas!A:A,"S07")+COUNTIFS(Citas!S:S,$A23,Citas!A:A,"S07")+COUNTIFS(Citas!T:T,$A23,Citas!A:A,"S07")+COUNTIFS(Citas!U:U,$A23,Citas!A:A,"S07")+COUNTIFS(Citas!V:V,$A23,Citas!A:A,"S07")+COUNTIFS(Citas!W:W,$A23,Citas!A:A,"S07")+COUNTIFS(Citas!X:X,$A23,Citas!A:A,"S07") -> 0 | C23: =COUNTIFS(Citas!R:R,$A23,Citas!A:A,"S08")+COUNTIFS(Citas!S:S,$A23,Citas!A:A,"S08")+COUNTIFS(Citas!T:T,$A23,Citas!A:A,"S08")+COUNTIFS(Citas!U:U,$A23,Citas!A:A,"S08")+COUNTIFS(Citas!V:V,$A23,Citas!A:A,"S08")+COUNTIFS(Citas!W:W,$A23,Citas!A:A,"S08")+COUNTIFS(Citas!X:X,$A23,Citas!A:A,"S08") -> 0 | D23: =COUNTIFS(Citas!R:R,$A23,Citas!A:A,"S09")+COUNTIFS(Citas!S:S,$A23,Citas!A:A,"S09")+COUNTIFS(Citas!T:T,$A23,Citas!A:A,"S09")+COUNTIFS(Citas!U:U,$A23,Citas!A:A,"S09")+COUNTIFS(Citas!V:V,$A23,Citas!A:A,"S09")+COUNTIFS(Citas!W:W,$A23,Citas!A:A,"S09")+COUNTIFS(Citas!X:X,$A23,Citas!A:A,"S09") -> 0 | E23: =COUNTIFS(Citas!R:R,$A23,Citas!A:A,"S10")+COUNTIFS(Citas!S:S,$A23,Citas!A:A,"S10")+COUNTIFS(Citas!T:T,$A23,Citas!A:A,"S10")+COUNTIFS(Citas!U:U,$A23,Citas!A:A,"S10")+COUNTIFS(Citas!V:V,$A23,Citas!A:A,"S10")+COUNTIFS(Citas!W:W,$A23,Citas!A:A,"S10")+COUNTIFS(Citas!X:X,$A23,Citas!A:A,"S10") -> 0 | F23: =COUNTIFS(Citas!R:R,$A23,Citas!A:A,"S11")+COUNTIFS(Citas!S:S,$A23,Citas!A:A,"S11")+COUNTIFS(Citas!T:T,$A23,Citas!A:A,"S11")+COUNTIFS(Citas!U:U,$A23,Citas!A:A,"S11")+COUNTIFS(Citas!V:V,$A23,Citas!A:A,"S11")+COUNTIFS(Citas!W:W,$A23,Citas!A:A,"S11")+COUNTIFS(Citas!X:X,$A23,Citas!A:A,"S11") -> 0 | G23: =COUNTIFS(Citas!R:R,$A23,Citas!A:A,"S12")+COUNTIFS(Citas!S:S,$A23,Citas!A:A,"S12")+COUNTIFS(Citas!T:T,$A23,Citas!A:A,"S12")+COUNTIFS(Citas!U:U,$A23,Citas!A:A,"S12")+COUNTIFS(Citas!V:V,$A23,Citas!A:A,"S12")+COUNTIFS(Citas!W:W,$A23,Citas!A:A,"S12")+COUNTIFS(Citas!X:X,$A23,Citas!A:A,"S12") -> 0 | H23: =COUNTIFS(Citas!R:R,$A23,Citas!A:A,"S13")+COUNTIFS(Citas!S:S,$A23,Citas!A:A,"S13")+COUNTIFS(Citas!T:T,$A23,Citas!A:A,"S13")+COUNTIFS(Citas!U:U,$A23,Citas!A:A,"S13")+COUNTIFS(Citas!V:V,$A23,Citas!A:A,"S13")+COUNTIFS(Citas!W:W,$A23,Citas!A:A,"S13")+COUNTIFS(Citas!X:X,$A23,Citas!A:A,"S13") -> 0 | I23: =COUNTIFS(Citas!R:R,$A23,Citas!A:A,"S14")+COUNTIFS(Citas!S:S,$A23,Citas!A:A,"S14")+COUNTIFS(Citas!T:T,$A23,Citas!A:A,"S14")+COUNTIFS(Citas!U:U,$A23,Citas!A:A,"S14")+COUNTIFS(Citas!V:V,$A23,Citas!A:A,"S14")+COUNTIFS(Citas!W:W,$A23,Citas!A:A,"S14")+COUNTIFS(Citas!X:X,$A23,Citas!A:A,"S14") -> 0 | J23: =COUNTIFS(Citas!R:R,$A23,Citas!A:A,"S16")+COUNTIFS(Citas!S:S,$A23,Citas!A:A,"S16")+COUNTIFS(Citas!T:T,$A23,Citas!A:A,"S16")+COUNTIFS(Citas!U:U,$A23,Citas!A:A,"S16")+COUNTIFS(Citas!V:V,$A23,Citas!A:A,"S16")+COUNTIFS(Citas!W:W,$A23,Citas!A:A,"S16")+COUNTIFS(Citas!X:X,$A23,Citas!A:A,"S16") -> 0
A24: Juan Correa | B24: =COUNTIFS(Citas!R:R,$A24,Citas!A:A,"S07")+COUNTIFS(Citas!S:S,$A24,Citas!A:A,"S07")+COUNTIFS(Citas!T:T,$A24,Citas!A:A,"S07")+COUNTIFS(Citas!U:U,$A24,Citas!A:A,"S07")+COUNTIFS(Citas!V:V,$A24,Citas!A:A,"S07")+COUNTIFS(Citas!W:W,$A24,Citas!A:A,"S07")+COUNTIFS(Citas!X:X,$A24,Citas!A:A,"S07") -> 0 | C24: =COUNTIFS(Citas!R:R,$A24,Citas!A:A,"S08")+COUNTIFS(Citas!S:S,$A24,Citas!A:A,"S08")+COUNTIFS(Citas!T:T,$A24,Citas!A:A,"S08")+COUNTIFS(Citas!U:U,$A24,Citas!A:A,"S08")+COUNTIFS(Citas!V:V,$A24,Citas!A:A,"S08")+COUNTIFS(Citas!W:W,$A24,Citas!A:A,"S08")+COUNTIFS(Citas!X:X,$A24,Citas!A:A,"S08") -> 0 | D24: =COUNTIFS(Citas!R:R,$A24,Citas!A:A,"S09")+COUNTIFS(Citas!S:S,$A24,Citas!A:A,"S09")+COUNTIFS(Citas!T:T,$A24,Citas!A:A,"S09")+COUNTIFS(Citas!U:U,$A24,Citas!A:A,"S09")+COUNTIFS(Citas!V:V,$A24,Citas!A:A,"S09")+COUNTIFS(Citas!W:W,$A24,Citas!A:A,"S09")+COUNTIFS(Citas!X:X,$A24,Citas!A:A,"S09") -> 0 | E24: =COUNTIFS(Citas!R:R,$A24,Citas!A:A,"S10")+COUNTIFS(Citas!S:S,$A24,Citas!A:A,"S10")+COUNTIFS(Citas!T:T,$A24,Citas!A:A,"S10")+COUNTIFS(Citas!U:U,$A24,Citas!A:A,"S10")+COUNTIFS(Citas!V:V,$A24,Citas!A:A,"S10")+COUNTIFS(Citas!W:W,$A24,Citas!A:A,"S10")+COUNTIFS(Citas!X:X,$A24,Citas!A:A,"S10") -> 0 | F24: =COUNTIFS(Citas!R:R,$A24,Citas!A:A,"S11")+COUNTIFS(Citas!S:S,$A24,Citas!A:A,"S11")+COUNTIFS(Citas!T:T,$A24,Citas!A:A,"S11")+COUNTIFS(Citas!U:U,$A24,Citas!A:A,"S11")+COUNTIFS(Citas!V:V,$A24,Citas!A:A,"S11")+COUNTIFS(Citas!W:W,$A24,Citas!A:A,"S11")+COUNTIFS(Citas!X:X,$A24,Citas!A:A,"S11") -> 0 | G24: =COUNTIFS(Citas!R:R,$A24,Citas!A:A,"S12")+COUNTIFS(Citas!S:S,$A24,Citas!A:A,"S12")+COUNTIFS(Citas!T:T,$A24,Citas!A:A,"S12")+COUNTIFS(Citas!U:U,$A24,Citas!A:A,"S12")+COUNTIFS(Citas!V:V,$A24,Citas!A:A,"S12")+COUNTIFS(Citas!W:W,$A24,Citas!A:A,"S12")+COUNTIFS(Citas!X:X,$A24,Citas!A:A,"S12") -> 0 | H24: =COUNTIFS(Citas!R:R,$A24,Citas!A:A,"S13")+COUNTIFS(Citas!S:S,$A24,Citas!A:A,"S13")+COUNTIFS(Citas!T:T,$A24,Citas!A:A,"S13")+COUNTIFS(Citas!U:U,$A24,Citas!A:A,"S13")+COUNTIFS(Citas!V:V,$A24,Citas!A:A,"S13")+COUNTIFS(Citas!W:W,$A24,Citas!A:A,"S13")+COUNTIFS(Citas!X:X,$A24,Citas!A:A,"S13") -> 0 | I24: =COUNTIFS(Citas!R:R,$A24,Citas!A:A,"S14")+COUNTIFS(Citas!S:S,$A24,Citas!A:A,"S14")+COUNTIFS(Citas!T:T,$A24,Citas!A:A,"S14")+COUNTIFS(Citas!U:U,$A24,Citas!A:A,"S14")+COUNTIFS(Citas!V:V,$A24,Citas!A:A,"S14")+COUNTIFS(Citas!W:W,$A24,Citas!A:A,"S14")+COUNTIFS(Citas!X:X,$A24,Citas!A:A,"S14") -> 0 | J24: =COUNTIFS(Citas!R:R,$A24,Citas!A:A,"S16")+COUNTIFS(Citas!S:S,$A24,Citas!A:A,"S16")+COUNTIFS(Citas!T:T,$A24,Citas!A:A,"S16")+COUNTIFS(Citas!U:U,$A24,Citas!A:A,"S16")+COUNTIFS(Citas!V:V,$A24,Citas!A:A,"S16")+COUNTIFS(Citas!W:W,$A24,Citas!A:A,"S16")+COUNTIFS(Citas!X:X,$A24,Citas!A:A,"S16") -> 0

Sheet Zonas
A1: DISTRIBUCIÓN GEOGRÁFICA DE CITAS
A3: Zona (Cód. Postal + Ciudad) | B3: Total Citas | C3: Total Unidades | D3: TK Promedio | E3: Tipos de Trabajo | F3: Técnico Sugerido
A4: 49143 | B4: 16 | C4: 76 | D4: 2.4 | E4: Installation + WC, WC
A5: 33014 | B5: 8 | C5: 45 | D5: 2.5 | E5: Installation, Installation + WC, WC
A6: 49328 | B6: 6 | C6: 32 | D6: 2.3 | E6: Installation + WC, Otro
A7: 33428 | B7: 6 | C7: 39 | D7: 2 | E7: Installation, Installation + WC
A8: 32816 | B8: 5 | C8: 69 | D8: 2.2 | E8: Installation + WC
A9: 34414 | B9: 5 | C9: 23 | D9: 2.4 | E9: Installation, Installation + WC
A10: 48155 | B10: 5 | C10: 35 | D10: 3.4 | E10: Installation, Installation + WC, Otro
A11: 49086 | B11: 4 | C11: 17 | D11: 2.5 | E11: Installation + WC, WC
A12: 49584 | B12: 4 | C12: 20 | D12: 2.2 | E12: Installation + WC
A13: 32549 | B13: 3 | C13: 14 | D13: 2.7 | E13: Installation + WC
A14: 49163 | B14: 3 | C14: 13 | D14: 2.3 | E14: Installation, Installation + WC
A15: 33428 Harsewinkel Ostheide 21 | B15: 1 | C15: 7 | D15: 2 | E15: Installation + WC
... A26: 32676 | B26: 1 | C26: 3 | D26: 2 | E26: Installation + WC

Sheet KPIs
A1: INDICADORES CLAVE DE RENDIMIENTO
A3: PROGRESO
A4: Total Citas Programadas | B4: =COUNTA(Citas!B5:B81) -> 77
A5: Completadas | B5: =COUNTIF(Citas!Y5:Y81,"Completado") -> 0
A6: Pendientes | B6: =COUNTIF(Citas!Y5:Y81,"Pendiente") -> 77
A7: En Progreso | B7: =COUNTIF(Citas!Y5:Y81,"En Progreso") -> 0
A8: Reprogramadas | B8: =COUNTIF(Citas!Y5:Y81,"Reprogramado") -> 0
A9: Canceladas | B9: =COUNTIF(Citas!Y5:Y81,"Cancelado") -> 0
A10: % Completado | B10: =IF(B4>0,B5/B4,0) -> 0
A12: VOLUMEN
A13: Total Unidades (WH+WE) | B13: =SUM(Citas!I5:I81) -> 457
A14: Total WH | B14: =SUMPRODUCT((Citas!J5:J81="WH")*Citas!I5:I81) -> 63
A15: Total WE | B15: =SUMPRODUCT((Citas!J5:J81="WE")*Citas!I5:I81) -> 394
A17: COSTOS
A18: Costo Total Estimado (€) | B18: =SUM(Citas!AB5:AB81) -> 0
A19: Costo Total Real (€) | B19: =SUM(Citas!AC5:AC81) -> 0
A20: Variación (€) | B20: =B19-B18 -> 0
A22: ASIGNACIÓN
A23: Citas Sin Técnico | B23: =COUNTBLANK(Citas!R5:R81) -> 77
A24: Técnicos Asignados (distintos) | B24: =SUMPRODUCT((Técnicos!B6:B12>0)*1) -> 0
A25: Evidencias Pendientes | B25: =COUNTIF(Citas!AD5:AD81,"Pendiente")+COUNTIF(Citas!AD5:AD81,"No") -> 0

Sheet Bloques Equipo
A1: BLOQUES DE DISPONIBILIDAD POR EQUIPO
A3: Equipo | B3: Fecha | C3: Día | D3: Hora Inicio | E3: Hora Fin | F3: Semana
A4: Team 1 | B4: 2026-02-09 | C4: Lunes | D4: 0.33333333 | E4: 0.75 | F4: S07
A5: Team 2 | B5: 2026-02-09 | C5: Lunes | D5: 0.33333333 | E5: 0.75 | F5: S07
A6: Team 1 | B6: 2026-02-10 | C6: Martes | D6: 0.33333333 | E6: 0.75 | F6: S07
A7: Team 2 | B7: 2026-02-10 | C7: Martes | D7: 0.33333333 | E7: 0.75 | F7: S07
A8: Team 1 | B8: 2026-02-11 | C8: Miércoles | D8: 0.33333333 | E8: 0.75 | F8: S07
A9: Team 2 | B9: 2026-02-11 | C9: Miércoles | D9: 0.33333333 | E9: 0.75 | F9: S07
A10: Team 1 | B10: 2026-02-12 | C10: Jueves | D10: 0.33333333 | E10: 0.75 | F10: S07
A11: Team 2 | B11: 2026-02-12 | C11: Jueves | D11: 0.33333333 | E11: 0.75 | F11: S07
A12: Team 1 | B12: 2026-02-13 | C12: Viernes | D12: 0.33333333 | E12: 0.75 | F12: S07
A13: Team 2 | B13: 2026-02-13 | C13: Viernes | D13: 0.33333333 | E13: 0.75 | F13: S07
A14: Team 1 | B14: 2026-02-16 | C14: Lunes | D14: 0.33333333 | E14: 0.75 | F14: S08
A15: Team 2 | B15: 2026-02-16 | C15: Lunes | D15: 0.33333333 | E15: 0.75 | F15: S08
... A77: Team 1 | B77: 2026-04-13 | C77: Lunes | D77: 0.33333333 | E77: 0.75 | F77: S16
